Traceback (most recent call last):
  File "/System/Library/Frameworks/Python.framework/Versions/2.7/lib/python2.7/runpy.py", line 162, in _run_module_as_main
    "__main__", fname, loader, pkg_name)
  File "/System/Library/Frameworks/Python.framework/Versions/2.7/lib/python2.7/runpy.py", line 72, in _run_code
    exec code in run_globals
  File "/System/Library/Frameworks/Python.framework/Versions/2.7/lib/python2.7/SimpleHTTPServer.py", line 220, in <module>
    test()
  File "/System/Library/Frameworks/Python.framework/Versions/2.7/lib/python2.7/SimpleHTTPServer.py", line 216, in test
    BaseHTTPServer.test(HandlerClass, ServerClass)
  File "/System/Library/Frameworks/Python.framework/Versions/2.7/lib/python2.7/BaseHTTPServer.py", line 598, in test
    httpd = ServerClass(server_address, HandlerClass)
  File "/System/Library/Frameworks/Python.framework/Versions/2.7/lib/python2.7/SocketServer.py", line 408, in __init__
    self.server_bind()
  File "/System/Library/Frameworks/Python.framework/Versions/2.7/lib/python2.7/BaseHTTPServer.py", line 108, in server_bind
    SocketServer.TCPServer.server_bind(self)
  File "/System/Library/Frameworks/Python.framework/Versions/2.7/lib/python2.7/SocketServer.py", line 419, in server_bind
    self.socket.bind(self.server_address)
  File "/System/Library/Frameworks/Python.framework/Versions/2.7/lib/python2.7/socket.py", line 224, in meth
    return getattr(self._sock,name)(*args)
socket.error: [Errno 48] Address already in use
Traceback (most recent call last):
  File "/System/Library/Frameworks/Python.framework/Versions/2.7/lib/python2.7/runpy.py", line 162, in _run_module_as_main
    "__main__", fname, loader, pkg_name)
  File "/System/Library/Frameworks/Python.framework/Versions/2.7/lib/python2.7/runpy.py", line 72, in _run_code
    exec code in run_globals
  File "/System/Library/Frameworks/Python.framework/Versions/2.7/lib/python2.7/SimpleHTTPServer.py", line 220, in <module>
    test()
  File "/System/Library/Frameworks/Python.framework/Versions/2.7/lib/python2.7/SimpleHTTPServer.py", line 216, in test
    BaseHTTPServer.test(HandlerClass, ServerClass)
  File "/System/Library/Frameworks/Python.framework/Versions/2.7/lib/python2.7/BaseHTTPServer.py", line 598, in test
    httpd = ServerClass(server_address, HandlerClass)
  File "/System/Library/Frameworks/Python.framework/Versions/2.7/lib/python2.7/SocketServer.py", line 408, in __init__
    self.server_bind()
  File "/System/Library/Frameworks/Python.framework/Versions/2.7/lib/python2.7/BaseHTTPServer.py", line 108, in server_bind
    SocketServer.TCPServer.server_bind(self)
  File "/System/Library/Frameworks/Python.framework/Versions/2.7/lib/python2.7/SocketServer.py", line 419, in server_bind
    self.socket.bind(self.server_address)
  File "/System/Library/Frameworks/Python.framework/Versions/2.7/lib/python2.7/socket.py", line 224, in meth
    return getattr(self._sock,name)(*args)
socket.error: [Errno 48] Address already in use
1.0.0.127.in-addr.arpa - - [12/Aug/2013 16:49:06] "GET /arrivals-and-departures-for-stop.json HTTP/1.1" 200 -
1.0.0.127.in-addr.arpa - - [12/Aug/2013 16:49:06] code 404, message File not found
1.0.0.127.in-addr.arpa - - [12/Aug/2013 16:49:06] "GET /favicon.ico HTTP/1.1" 404 -
1.0.0.127.in-addr.arpa - - [12/Aug/2013 16:49:18] "GET /arrivals-and-departures-for-stop.json?key=onebusaway.forest.usf.edu-f75b1e48-80c4-4880-a294-e353e13bd9d2&lat=28.06385&lon=-82.41318 HTTP/1.1" 200 -
